Workbook
Name Slicer_Diabetes_Status: #N/A
Name Slicer_Weight_Status: #N/A

Sheet Sheet1

Sheet Customer Names
A1: Customer ID | B1: name | C1: Tittle | D1: First name | E1: Last name | F1: Proper Name
A2: Id1 | B2: Hawks, Ms. Kelly | C2: =MID(B2,FIND(",",B2)+2,FIND(".",B2)-FIND(",",B2)) -> Ms. | D2: =TRIM(MID(B2,FIND(".",B2)+1,LEN(B2))) -> Kelly | E2: =LEFT(B2,FIND(",",B2)-1) -> Hawks | F2: =CONCATENATE(C2,"",D2," ",E2) -> Ms. Kelly Hawks
A3: Id10 | B3: Benner, Ms. Brooke N. | C3: =MID(B3,FIND(",",B3)+2,FIND(".",B3)-FIND(",",B3)) -> Ms. | D3: =TRIM(MID(B3,FIND(".",B3)+1,LEN(B3))) -> Brooke N. | E3: =LEFT(B3,FIND(",",B3)-1) -> Benner | F3: =CONCATENATE(C3,"",D3," ",E3) -> Ms. Brooke N. Benner
A4: Id100 | B4: Gollins, Mr. Daniel | C4: =MID(B4,FIND(",",B4)+2,FIND(".",B4)-FIND(",",B4)) -> Mr. | D4: =TRIM(MID(B4,FIND(".",B4)+1,LEN(B4))) -> Daniel | E4: =LEFT(B4,FIND(",",B4)-1) -> Gollins | F4: =CONCATENATE(C4,"",D4," ",E4) -> Mr. Daniel Gollins
A5: Id1000 | B5: Schaefer, Mrs. Stephanie A | C5: =MID(B5,FIND(",",B5)+2,FIND(".",B5)-FIND(",",B5)) -> Mrs. | D5: =TRIM(MID(B5,FIND(".",B5)+1,LEN(B5))) -> Stephanie A | E5: =LEFT(B5,FIND(",",B5)-1) -> Schaefer | F5: =CONCATENATE(C5,"",D5," ",E5) -> Mrs. Stephanie A Schaefer
A6: Id1001 | B6: D'Alessandro, Mr. Patrick | C6: =MID(B6,FIND(",",B6)+2,FIND(".",B6)-FIND(",",B6)) -> Mr. | D6: =TRIM(MID(B6,FIND(".",B6)+1,LEN(B6))) -> Patrick | E6: =LEFT(B6,FIND(",",B6)-1) -> D'Alessandro | F6: =CONCATENATE(C6,"",D6," ",E6) -> Mr. Patrick D'Alessandro
A7: Id1002 | B7: Wyss, Mrs. Krista | C7: =MID(B7,FIND(",",B7)+2,FIND(".",B7)-FIND(",",B7)) -> Mrs. | D7: =TRIM(MID(B7,FIND(".",B7)+1,LEN(B7))) -> Krista | E7: =LEFT(B7,FIND(",",B7)-1) -> Wyss | F7: =CONCATENATE(C7,"",D7," ",E7) -> Mrs. Krista Wyss
A8: Id1003 | B8: Rose, Ms. Jenessa | C8: =MID(B8,FIND(",",B8)+2,FIND(".",B8)-FIND(",",B8)) -> Ms. | D8: =TRIM(MID(B8,FIND(".",B8)+1,LEN(B8))) -> Jenessa | E8: =LEFT(B8,FIND(",",B8)-1) -> Rose | F8: =CONCATENATE(C8,"",D8," ",E8) -> Ms. Jenessa Rose
A9: Id1004 | B9: Hopper, Mr. Ryan M. | C9: =MID(B9,FIND(",",B9)+2,FIND(".",B9)-FIND(",",B9)) -> Mr. | D9: =TRIM(MID(B9,FIND(".",B9)+1,LEN(B9))) -> Ryan M. | E9: =LEFT(B9,FIND(",",B9)-1) -> Hopper | F9: =CONCATENATE(C9,"",D9," ",E9) -> Mr. Ryan M. Hopper
A10: Id1005 | B10: Finneran, Mr. Thomas | C10: =MID(B10,FIND(",",B10)+2,FIND(".",B10)-FIND(",",B10)) -> Mr. | D10: =TRIM(MID(B10,FIND(".",B10)+1,LEN(B10))) -> Thomas | E10: =LEFT(B10,FIND(",",B10)-1) -> Finneran | F10: =CONCATENATE(C10,"",D10," ",E10) -> Mr. Thomas Finneran
A11: Id1006 | B11: Basham, Ms. Amanda N. | C11: =MID(B11,FIND(",",B11)+2,FIND(".",B11)-FIND(",",B11)) -> Ms. | D11: =TRIM(MID(B11,FIND(".",B11)+1,LEN(B11))) -> Amanda N. | E11: =LEFT(B11,FIND(",",B11)-1) -> Basham | F11: =CONCATENATE(C11,"",D11," ",E11) -> Ms. Amanda N. Basham
A12: Id1007 | B12: Inman, Ms. Teresa P. | C12: =MID(B12,FIND(",",B12)+2,FIND(".",B12)-FIND(",",B12)) -> Ms. | D12: =TRIM(MID(B12,FIND(".",B12)+1,LEN(B12))) -> Teresa P. | E12: =LEFT(B12,FIND(",",B12)-1) -> Inman | F12: =CONCATENATE(C12,"",D12," ",E12) -> Ms. Teresa P. Inman
A13: Id1008 | B13: Oscal, Mr. Dorian | C13: =MID(B13,FIND(",",B13)+2,FIND(".",B13)-FIND(",",B13)) -> Mr. | D13: =TRIM(MID(B13,FIND(".",B13)+1,LEN(B13))) -> Dorian | E13: =LEFT(B13,FIND(",",B13)-1) -> Oscal | F13: =CONCATENATE(C13,"",D13," ",E13) -> Mr. Dorian Oscal
... A2336: Id999 | B2336: Campbell, Mr. Jonathon M. | C2336: =MID(B2336,FIND(",",B2336)+2,FIND(".",B2336)-FIND(",",B2336)) -> Mr. | D2336: =TRIM(MID(B2336,FIND(".",B2336)+1,LEN(B2336))) -> Jonathon M. | E2336: =LEFT(B2336,FIND(",",B2336)-1) -> Campbell | F2336: =CONCATENATE(C2336,"",D2336," ",E2336) -> Mr. Jonathon M. Campbell

Sheet Sheet12
B3: Column Labels
A4: Row Labels | B4: No | C4: Yes | D4: Grand Total
A5: No
A6: yes
A7: Grand Total

Sheet Sheet14
A1: Data returned for Count of Customer ID, No (First 1000 rows).
A3: Range[Customer ID] | B3: Range[First Name] | C3: Range[BMI] | D3: Range[HBA1C] | E3: Range[Heart Issues] | F3: Range[Any Transplants] | G3: Range[Cancer history] | H3: Range[NumberOfMajorSurgeries] | I3: Range[smoker] | J3: Range[Weight Status] | K3: Range[Diabetes Status] | L3: Range[Date of Birth] | M3: Range[charges] | N3: Range[Hospital tier] | O3: Range[City tier] | P3: Range[State ID] | Q3: Range[Age]
A4: Id2285 | B4: Alvaro Sr. | C4: 41.14 | D4: 6.02 | E4: No | F4: yes | G4: No | H4: 1 | I4: No | J4: Obesity | K4: Prediabetes | L4: 10-Jun-2004 | M4: 1146.8 | N4: tier - 2 | O4: tier - 2 | P4: R1013 | Q4: 10
A5: Id2283 | B5: David | C5: 43.01 | D5: 5.44 | E5: No | F5: yes | G5: No | H5: 1 | I5: No | J5: Obesity | K5: Normal | L5: 18-Jul-2004 | M5: 1149.4 | N5: tier - 2 | O5: tier - 2 | P5: R1013 | Q5: 18
A6: Id2277 | B6: Abby L. | C6: 22.79 | D6: 6.15 | E6: yes | F6: No | G6: Yes | H6: 1 | I6: No | J6: Normal Weight | K6: Prediabetes | L6: 28-Jun-1997 | M6: 1178.07 | N6: tier - 2 | O6: tier - 2 | P6: R1013 | Q6: 28
A7: Id2268 | B7: Christi A. | C7: 21.98 | D7: 7.03 | E7: No | F7: No | G7: No | H7: 0 | I7: No | J7: Normal Weight | K7: Diabetes | L7: 12-Dec-2002 | M7: 1237 | N7: tier - 2 | O7: tier - 2 | P7: R1013 | Q7: 12
A8: Id2266 | B8: Elizabeth S. | C8: 21.87 | D8: 8.59 | E8: No | F8: No | G8: No | H8: 0 | I8: No | J8: Normal Weight | K8: Diabetes | L8: 1-Jul-2002 | M8: 1241 | N8: tier - 2 | O8: tier - 2 | P8: R1013 | Q8: 1
A9: Id2261 | B9: Julia | C9: 17.44 | D9: 4.42 | E9: yes | F9: No | G9: Yes | H9: 1 | I9: No | J9: Underweight | K9: Normal | L9: 4-Nov-1997 | M9: 1253 | N9: tier - 2 | O9: tier - 2 | P9: R1013 | Q9: 4
A10: Id2251 | B10: Natalie | C10: 16.13 | D10: 5.56 | E10: No | F10: yes | G10: No | H10: 1 | I10: No | J10: Underweight | K10: Normal | L10: 26-Jun-2000 | M10: 1286 | N10: tier - 2 | O10: tier - 2 | P10: R1013 | Q10: 26
A11: Id2250 | B11: Mary | C11: 23.88 | D11: 4.51 | E11: No | F11: No | G11: No | H11: 1 | I11: No | J11: Normal Weight | K11: Normal | L11: 4-Jun-1998 | M11: 1290.93 | N11: tier - 2 | O11: tier - 2 | P11: R1013 | Q11: 4
A12: Id2247 | B12: Jessica | C12: 20.43 | D12: 4.54 | E12: No | F12: No | G12: No | H12: 0 | I12: No | J12: Normal Weight | K12: Normal | L12: 2-Dec-1999 | M12: 1304 | N12: tier - 2 | O12: tier - 2 | P12: R1013 | Q12: 2
A13: Id2246 | B13: Melanie | C13: 20.88 | D13: 7.4 | E13: No | F13: No | G13: No | H13: 0 | I13: No | J13: Normal Weight | K13: Diabetes | L13: 13-Oct-2002 | M13: 1315 | N13: tier - 2 | O13: tier - 2 | P13: R1013 | Q13: 13
A14: Id2239 | B14: William R | C14: 18.58 | D14: 6.22 | E14: No | F14: No | G14: No | H14: 0 | I14: No | J14: Normal Weight | K14: Prediabetes | L14: 6-Jul-1999 | M14: 1389 | N14: tier - 2 | O14: tier - 2 | P14: R1013 | Q14: 6
A15: Id2238 | B15: Christopher S. | C15: 18.5 | D15: 11.84 | E15: No | F15: No | G15: No | H15: 0 | I15: No | J15: Normal Weight | K15: Diabetes | L15: 14-Nov-2002 | M15: 1390 | N15: tier - 2 | O15: tier - 2 | P15: R1013 | Q15: 14
... A1003: Id956 | B1003: Meghan E | C1003: 39.22 | D1003: 5.62 | E1003: yes | F1003: No | G1003: No | H1003: 1 | I1003: No | J1003: Obesity | K1003: Normal | L1003: 12-Jun-1988 | M1003: 11524.25 | N1003: tier - 3 | O1003: tier - 1 | P1003: R1026 | Q1003: 12

Sheet Sheet15
A1: Data returned for Count of NumberOfMajorSurgeries (First 1000 rows).
A3: Range[Customer ID] | B3: Range[First Name] | C3: Range[BMI] | D3: Range[HBA1C] | E3: Range[Heart Issues] | F3: Range[Any Transplants] | G3: Range[Cancer history] | H3: Range[NumberOfMajorSurgeries] | I3: Range[smoker] | J3: Range[Weight Status] | K3: Range[Diabetes Status] | L3: Range[Date of Birth] | M3: Range[charges] | N3: Range[Hospital tier] | O3: Range[City tier] | P3: Range[State ID] | Q3: Range[Age]
A4: Id2285 | B4: Alvaro Sr. | C4: 41.14 | D4: 6.02 | E4: No | F4: yes | G4: No | H4: 1 | I4: No | J4: Obesity | K4: Prediabetes | L4: 10-Jun-2004 | M4: 1146.8 | N4: tier - 2 | O4: tier - 2 | P4: R1013 | Q4: 10
A5: Id2283 | B5: David | C5: 43.01 | D5: 5.44 | E5: No | F5: yes | G5: No | H5: 1 | I5: No | J5: Obesity | K5: Normal | L5: 18-Jul-2004 | M5: 1149.4 | N5: tier - 2 | O5: tier - 2 | P5: R1013 | Q5: 18
A6: Id2277 | B6: Abby L. | C6: 22.79 | D6: 6.15 | E6: yes | F6: No | G6: Yes | H6: 1 | I6: No | J6: Normal Weight | K6: Prediabetes | L6: 28-Jun-1997 | M6: 1178.07 | N6: tier - 2 | O6: tier - 2 | P6: R1013 | Q6: 28
A7: Id2268 | B7: Christi A. | C7: 21.98 | D7: 7.03 | E7: No | F7: No | G7: No | H7: 0 | I7: No | J7: Normal Weight | K7: Diabetes | L7: 12-Dec-2002 | M7: 1237 | N7: tier - 2 | O7: tier - 2 | P7: R1013 | Q7: 12
A8: Id2266 | B8: Elizabeth S. | C8: 21.87 | D8: 8.59 | E8: No | F8: No | G8: No | H8: 0 | I8: No | J8: Normal Weight | K8: Diabetes | L8: 1-Jul-2002 | M8: 1241 | N8: tier - 2 | O8: tier - 2 | P8: R1013 | Q8: 1
A9: Id2261 | B9: Julia | C9: 17.44 | D9: 4.42 | E9: yes | F9: No | G9: Yes | H9: 1 | I9: No | J9: Underweight | K9: Normal | L9: 4-Nov-1997 | M9: 1253 | N9: tier - 2 | O9: tier - 2 | P9: R1013 | Q9: 4
A10: Id2251 | B10: Natalie | C10: 16.13 | D10: 5.56 | E10: No | F10: yes | G10: No | H10: 1 | I10: No | J10: Underweight | K10: Normal | L10: 26-Jun-2000 | M10: 1286 | N10: tier - 2 | O10: tier - 2 | P10: R1013 | Q10: 26
A11: Id2250 | B11: Mary | C11: 23.88 | D11: 4.51 | E11: No | F11: No | G11: No | H11: 1 | I11: No | J11: Normal Weight | K11: Normal | L11: 4-Jun-1998 | M11: 1290.93 | N11: tier - 2 | O11: tier - 2 | P11: R1013 | Q11: 4
A12: Id2247 | B12: Jessica | C12: 20.43 | D12: 4.54 | E12: No | F12: No | G12: No | H12: 0 | I12: No | J12: Normal Weight | K12: Normal | L12: 2-Dec-1999 | M12: 1304 | N12: tier - 2 | O12: tier - 2 | P12: R1013 | Q12: 2
A13: Id2246 | B13: Melanie | C13: 20.88 | D13: 7.4 | E13: No | F13: No | G13: No | H13: 0 | I13: No | J13: Normal Weight | K13: Diabetes | L13: 13-Oct-2002 | M13: 1315 | N13: tier - 2 | O13: tier - 2 | P13: R1013 | Q13: 13
A14: Id2239 | B14: William R | C14: 18.58 | D14: 6.22 | E14: No | F14: No | G14: No | H14: 0 | I14: No | J14: Normal Weight | K14: Prediabetes | L14: 6-Jul-1999 | M14: 1389 | N14: tier - 2 | O14: tier - 2 | P14: R1013 | Q14: 6
A15: Id2238 | B15: Christopher S. | C15: 18.5 | D15: 11.84 | E15: No | F15: No | G15: No | H15: 0 | I15: No | J15: Normal Weight | K15: Diabetes | L15: 14-Nov-2002 | M15: 1390 | N15: tier - 2 | O15: tier - 2 | P15: R1013 | Q15: 14
... A1003: Id1422 | B1003: Estuardo F | C1003: 39.805 | D1003: 5.91 | E1003: No | F1003: No | G1003: No | H1003: 0 | I1003: No | J1003: Obesity | K1003: Prediabetes | L1003: 30-Sep-1977 | M1003: 7448.4 | N1003: tier - 3 | O1003: tier - 3 | P1003: R1017 | Q1003: 30

Sheet Sheet16
A1: Data returned for Average of charges, Obesity, Diabetes (First 1000 rows).
A3: Range[Customer ID] | B3: Range[First Name] | C3: Range[BMI] | D3: Range[HBA1C] | E3: Range[Heart Issues] | F3: Range[Any Transplants] | G3: Range[Cancer history] | H3: Range[NumberOfMajorSurgeries] | I3: Range[smoker] | J3: Range[Weight Status] | K3: Range[Diabetes Status] | L3: Range[Date of Birth] | M3: Range[charges] | N3: Range[Hospital tier] | O3: Range[City tier] | P3: Range[State ID] | Q3: Range[Age]
A4: Id1334 | B4: Dino | C4: 36.85 | D4: 8.8 | E4: No | F4: No | G4: No | H4: 2 | I4: No | J4: Obesity | K4: Diabetes | L4: 3-Sep-1973 | M4: 8125.78 | N4: tier - 2 | O4: tier - 2 | P4: R1013 | Q4: 3
A5: Id1317 | B5: Gretchen K. | C5: 31.13 | D5: 10.1 | E5: No | F5: No | G5: No | H5: 0 | I5: No | J5: Obesity | K5: Diabetes | L5: 22-Dec-1974 | M5: 8280.62 | N5: tier - 2 | O5: tier - 2 | P5: R1013 | Q5: 22
A6: Id43 | B6: Nicole | C6: 38.06 | D6: 6.98 | E6: No | F6: No | G6: No | H6: 0 | I6: yes | J6: Obesity | K6: Diabetes | L6: 29-Oct-1971 | M6: 44400.41 | N6: tier - 2 | O6: tier - 2 | P6: R1013 | Q6: 29
A7: Id38 | B7: Anna H. | C7: 32.45 | D7: 11.91 | E7: No | F7: No | G7: No | H7: 0 | I7: yes | J7: Obesity | K7: Diabetes | L7: 17-Dec-1962 | M7: 45008.96 | N7: tier - 2 | O7: tier - 2 | P7: R1013 | Q7: 17
A8: Id2237 | B8: Daniel C | C8: 33.33 | D8: 9.79 | E8: No | F8: No | G8: No | H8: 0 | I8: No | J8: Obesity | K8: Diabetes | L8: 22-Dec-2002 | M8: 1391.53 | N8: tier - 2 | O8: tier - 1 | P8: R1013 | Q8: 22
A9: Id1780 | B9: Colleen M | C9: 29.92 | D9: 10.97 | E9: yes | F9: No | G9: No | H9: 1 | I9: No | J9: Obesity | K9: Diabetes | L9: 27-Oct-1986 | M9: 4889.04 | N9: tier - 2 | O9: tier - 1 | P9: R1013 | Q9: 27
A10: Id1672 | B10: Jake | C10: 33.55 | D10: 10.9 | E10: yes | F10: No | G10: No | H10: 0 | I10: No | J10: Obesity | K10: Diabetes | L10: 15-Jun-1981 | M10: 5699.84 | N10: tier - 2 | O10: tier - 3 | P10: R1013 | Q10: 15
A11: Id1610 | B11: Amy L | C11: 31.02 | D11: 11.63 | E11: yes | F11: No | G11: No | H11: 0 | I11: No | J11: Obesity | K11: Diabetes | L11: 22-Nov-1981 | M11: 6185.32 | N11: tier - 2 | O11: tier - 1 | P11: R1013 | Q11: 22
A12: Id1373 | B12: Travis | C12: 40.15 | D12: 11.84 | E12: No | F12: No | G12: No | H12: 0 | I12: No | J12: Obesity | K12: Diabetes | L12: 9-Nov-1974 | M12: 7804.16 | N12: tier - 2 | O12: tier - 3 | P12: R1013 | Q12: 9
A13: Id1316 | B13: Lisa | C13: 33.33 | D13: 7.61 | E13: No | F13: No | G13: No | H13: 0 | I13: No | J13: Obesity | K13: Diabetes | L13: 6-Jun-1974 | M13: 8283.68 | N13: tier - 2 | O13: tier - 3 | P13: R1013 | Q13: 6
A14: Id1214 | B14: Tiffany | C14: 34.1 | D14: 8.45 | E14: No | F14: No | G14: No | H14: 0 | I14: No | J14: Obesity | K14: Diabetes | L14: 2-Jul-1971 | M14: 9283.56 | N14: tier - 2 | O14: tier - 3 | P14: R1013 | Q14: 2
A15: Id705 | B15: Candace N | C15: 35.97 | D15: 11.08 | E15: No | F15: No | G15: No | H15: 3 | I15: No | J15: Obesity | K15: Diabetes | L15: 15-Oct-1958 | M15: 14313.85 | N15: tier - 2 | O15: tier - 3 | P15: R1013 | Q15: 15
... A440: Id305 | B440: Christine | C440: 29.92 | D440: 11.99 | E440: yes | F440: No | G440: No | H440: 2 | I440: yes | J440: Obesity | K440: Diabetes | L440: 9-Sep-1961 | M440: 30942.19 | N440: tier - 2 | O440: tier - 2 | P440: R1013 | Q440: 9

Sheet Pivot table
A3: Count of Customer ID | B3: Column Labels
A4: Row Labels | B4: No | C4: Yes | D4: Grand Total | J4: Row Labels | K4: Count of NumberOfMajorSurgeries | L4: Average of HBA1C
A5: No | B5: 1540 | C5: 307 | D5: 1847 | J5: No | K5: 2191 | L5: 6.6704427
A6: yes | B6: 404 | C6: 84 | D6: 488 | J6: yes | K6: 144 | L6: 5.1876389
A7: Grand Total | B7: 1944 | C7: 391 | D7: 2335 | J7: Grand Total | K7: 2335 | L7: 6.5789979
A18: Average of charges | B18: Column Labels
A19: Row Labels | B19: Diabetes | C19: Normal | D19: Prediabetes | E19: Grand Total | I19: Average of charges | J19: Column Labels
A20: Normal Weight | B20: 12509.815 | C20: 7897.0779 | D20: 10389.963 | E20: 9842.5103 | I20: Row Labels | J20: ? | K20: tier - 1 | L20: tier - 2 | M20: tier - 3 | N20: Grand Total
A21: Obesity | B21: 19103.403 | C21: 15140.415 | D21: 15502.742 | E21: 16612.253 | I21: R1011 | K21: 33081.374 | L21: 18997.281 | M21: 9250.3618 | N21: 19466.246
A22: Overweight | B22: 13886.681 | C22: 10376.643 | D22: 10008.416 | E22: 11409.791 | I22: R1012 | K22: 26111.458 | L22: 10334.279 | M22: 10179.942 | N22: 12016.474
A23: Underweight | B23: 7424.9523 | C23: 6911.0056 | D23: 5626.0918 | E23: 6899.3175 | I23: R1013 | J23: 700 | K23: 31328.102 | L23: 8459.9777 | M23: 6890.7568 | N23: 10514.94
A24: Grand Total | B24: 15973.539 | C24: 12090.723 | D24: 12690.985 | E24: 13529.918 | I24: R1014 | K24: 13891.86 | L24: 2395.17 | M24: 16950.485 | N24: 13478.057
I25: R1015 | K25: 21523.52 | L25: 15675.543 | M25: 7570.755 | N25: 13948.61
I26: R1016 | K26: 39868.616 | L26: 16075.963 | M26: 8133.0084 | N26: 13589.263
I27: R1017 | K27: 34070.596 | L27: 11365.622 | M27: 8667.3662 | N27: 14806.108
I28: R1018 | K28: 33475.82 | L28: 10139.553 | M28: 12570.97 | N28: 13272.787
I29: R1019 | K29: 27621.61 | L29: 8116.72 | M29: 12706.976 | N29: 13633.143
I30: R1020 | L30: 6760.5433 | M30: 11716.453 | N30: 9238.4983
I31: R1021 | L31: 7668.1787 | M31: 11518.786 | N31: 8933.3781
I32: R1022 | L32: 10102.027 | M32: 11637.812 | N32: 10650.521
I33: R1023 | K33: 18261.757 | L33: 13457.095 | M33: 12785.637 | N33: 13786.149
B34: Row Labels | C34: Average of BMI | I34: R1024 | K34: 32732.187 | L34: 10174.346 | M34: 13360.979 | N34: 12865.149
B35: 1 | C35: 30.524236 | I35: R1025 | L35: 6886.0368 | M35: 10510.314 | N35: 8788.7823
B36: 2 | C36: 31.146301 | I36: R1026 | K36: 18709.798 | L36: 11919.608 | M36: 12296.78 | N36: 12489.921
B37: 3 | C37: 30.410956 | I37: Grand Total | J37: 700 | K37: 30189.68 | L37: 11873.62 | M37: 9462.2693 | N37: 13523.517
B38: 4 | C38: 30.608976
B39: 5 | C39: 29.289398
B40: 6 | C40: 31.054485
B41: 7 | C41: 30.234857
B42: 8 | C42: 31.981127
B43: 9 | C43: 29.426322
B44: 10 | C44: 30.368235
B45: 11 | C45: 28.150064
B46: 12 | C46: 31.343859
B47: 13 | C47: 32.562817
B48: 14 | C48: 30.389824
B49: 15 | C49: 30.183333
... B64: 30 | C64: 32.396284
B65: Grand Total | C65: 30.972649

Sheet Dash board

Sheet Health Care
A1: Customer ID | B1: First Name | C1: BMI | D1: HBA1C | E1: Heart Issues | F1: Any Transplants | G1: Cancer history | H1: NumberOfMajorSurgeries | I1: smoker | J1: Weight Status | K1: Diabetes Status | L1: Date of Birth | M1: charges | N1: Hospital tier | O1: City tier | P1: State ID | Q1: Age
A2: Id2285 | B2: =VLOOKUP(A2,'Customer Names'!A:F,4,FALSE) -> Alvaro Sr. | C2: =VLOOKUP(A2,'Medical Examinations'!A:J,2,FALSE) -> 41.14 | D2: =VLOOKUP(A2,'Medical Examinations'!A:J,4,FALSE) -> 6.02 | E2: =VLOOKUP(A2,'Medical Examinations'!A:J,6,FALSE) -> No | F2: =VLOOKUP(A2,'Medical Examinations'!A:J,7,FALSE) -> yes | G2: =VLOOKUP(A2,'Medical Examinations'!A:J,8,FALSE) -> No | H2: =VLOOKUP(A2,'Medical Examinations'!A:J,9,FALSE) -> 1 | I2: =VLOOKUP(A2,'Medical Examinations'!A:J,10,FALSE) -> No | J2: =VLOOKUP(A2,'Medical Examinations'!A:J,3,FALSE) -> Obesity | K2: =VLOOKUP(A2,'Medical Examinations'!A:J,5,FALSE) -> Prediabetes | L2: =VLOOKUP(A2,'Hospitalisation Details'!A:K,5,FALSE) -> 10-Jun-2004 | M2: =VLOOKUP(A2,'Hospitalisation Details'!A:K,8,FALSE) -> 1146.8 | N2: =VLOOKUP(A2,'Hospitalisation Details'!A:K,9,FALSE) -> tier - 2 | O2: =VLOOKUP(A2,'Hospitalisation Details'!A:K,10,FALSE) -> tier - 2 | P2: =VLOOKUP(A2,'Hospitalisation Details'!A:K,11,FALSE) -> R1013 | Q2: =VLOOKUP(A2,'Hospitalisation Details'!A:K,4,FALSE) -> 10
A3: Id2283 | B3: =VLOOKUP(A3,'Customer Names'!A:F,4,FALSE) -> David | C3: =VLOOKUP(A3,'Medical Examinations'!A:J,2,FALSE) -> 43.01 | D3: =VLOOKUP(A3,'Medical Examinations'!A:J,4,FALSE) -> 5.44 | E3: =VLOOKUP(A3,'Medical Examinations'!A:J,6,FALSE) -> No | F3: =VLOOKUP(A3,'Medical Examinations'!A:J,7,FALSE) -> yes | G3: =VLOOKUP(A3,'Medical Examinations'!A:J,8,FALSE) -> No | H3: =VLOOKUP(A3,'Medical Examinations'!A:J,9,FALSE) -> 1 | I3: =VLOOKUP(A3,'Medical Examinations'!A:J,10,FALSE) -> No | J3: =VLOOKUP(A3,'Medical Examinations'!A:J,3,FALSE) -> Obesity | K3: =VLOOKUP(A3,'Medical Examinations'!A:J,5,FALSE) -> Normal | L3: =VLOOKUP(A3,'Hospitalisation Details'!A:K,5,FALSE) -> 18-Jul-2004 | M3: =VLOOKUP(A3,'Hospitalisation Details'!A:K,8,FALSE) -> 1149.4 | N3: =VLOOKUP(A3,'Hospitalisation Details'!A:K,9,FALSE) -> tier - 2 | O3: =VLOOKUP(A3,'Hospitalisation Details'!A:K,10,FALSE) -> tier - 2 | P3: =VLOOKUP(A3,'Hospitalisation Details'!A:K,11,FALSE) -> R1013 | Q3: =VLOOKUP(A3,'Hospitalisation Details'!A:K,4,FALSE) -> 18
A4: Id2277 | B4: =VLOOKUP(A4,'Customer Names'!A:F,4,FALSE) -> Abby L. | C4: =VLOOKUP(A4,'Medical Examinations'!A:J,2,FALSE) -> 22.79 | D4: =VLOOKUP(A4,'Medical Examinations'!A:J,4,FALSE) -> 6.15 | E4: =VLOOKUP(A4,'Medical Examinations'!A:J,6,FALSE) -> yes | F4: =VLOOKUP(A4,'Medical Examinations'!A:J,7,FALSE) -> No | G4: =VLOOKUP(A4,'Medical Examinations'!A:J,8,FALSE) -> Yes | H4: =VLOOKUP(A4,'Medical Examinations'!A:J,9,FALSE) -> 1 | I4: =VLOOKUP(A4,'Medical Examinations'!A:J,10,FALSE) -> No | J4: =VLOOKUP(A4,'Medical Examinations'!A:J,3,FALSE) -> Normal Weight | K4: =VLOOKUP(A4,'Medical Examinations'!A:J,5,FALSE) -> Prediabetes | L4: =VLOOKUP(A4,'Hospitalisation Details'!A:K,5,FALSE) -> 28-Jun-1997 | M4: =VLOOKUP(A4,'Hospitalisation Details'!A:K,8,FALSE) -> 1178.07 | N4: =VLOOKUP(A4,'Hospitalisation Details'!A:K,9,FALSE) -> tier - 2 | O4: =VLOOKUP(A4,'Hospitalisation Details'!A:K,10,FALSE) -> tier - 2 | P4: =VLOOKUP(A4,'Hospitalisation Details'!A:K,11,FALSE) -> R1013 | Q4: =VLOOKUP(A4,'Hospitalisation Details'!A:K,4,FALSE) -> 28
A5: Id2268 | B5: =VLOOKUP(A5,'Customer Names'!A:F,4,FALSE) -> Christi A. | C5: =VLOOKUP(A5,'Medical Examinations'!A:J,2,FALSE) -> 21.98 | D5: =VLOOKUP(A5,'Medical Examinations'!A:J,4,FALSE) -> 7.03 | E5: =VLOOKUP(A5,'Medical Examinations'!A:J,6,FALSE) -> No | F5: =VLOOKUP(A5,'Medical Examinations'!A:J,7,FALSE) -> No | G5: =VLOOKUP(A5,'Medical Examinations'!A:J,8,FALSE) -> No | H5: =VLOOKUP(A5,'Medical Examinations'!A:J,9,FALSE) -> 0 | I5: =VLOOKUP(A5,'Medical Examinations'!A:J,10,FALSE) -> No | J5: =VLOOKUP(A5,'Medical Examinations'!A:J,3,FALSE) -> Normal Weight | K5: =VLOOKUP(A5,'Medical Examinations'!A:J,5,FALSE) -> Diabetes | L5: =VLOOKUP(A5,'Hospitalisation Details'!A:K,5,FALSE) -> 12-Dec-2002 | M5: =VLOOKUP(A5,'Hospitalisation Details'!A:K,8,FALSE) -> 1237 | N5: =VLOOKUP(A5,'Hospitalisation Details'!A:K,9,FALSE) -> tier - 2 | O5: =VLOOKUP(A5,'Hospitalisation Details'!A:K,10,FALSE) -> tier - 2 | P5: =VLOOKUP(A5,'Hospitalisation Details'!A:K,11,FALSE) -> R1013 | Q5: =VLOOKUP(A5,'Hospitalisation Details'!A:K,4,FALSE) -> 12
A6: Id2266 | B6: =VLOOKUP(A6,'Customer Names'!A:F,4,FALSE) -> Elizabeth S. | C6: =VLOOKUP(A6,'Medical Examinations'!A:J,2,FALSE) -> 21.87 | D6: =VLOOKUP(A6,'Medical Examinations'!A:J,4,FALSE) -> 8.59 | E6: =VLOOKUP(A6,'Medical Examinations'!A:J,6,FALSE) -> No | F6: =VLOOKUP(A6,'Medical Examinations'!A:J,7,FALSE) -> No | G6: =VLOOKUP(A6,'Medical Examinations'!A:J,8,FALSE) -> No | H6: =VLOOKUP(A6,'Medical Examinations'!A:J,9,FALSE) -> 0 | I6: =VLOOKUP(A6,'Medical Examinations'!A:J,10,FALSE) -> No | J6: =VLOOKUP(A6,'Medical Examinations'!A:J,3,FALSE) -> Normal Weight | K6: =VLOOKUP(A6,'Medical Examinations'!A:J,5,FALSE) -> Diabetes | L6: =VLOOKUP(A6,'Hospitalisation Details'!A:K,5,FALSE) -> 1-Jul-2002 | M6: =VLOOKUP(A6,'Hospitalisation Details'!A:K,8,FALSE) -> 1241 | N6: =VLOOKUP(A6,'Hospitalisation Details'!A:K,9,FALSE) -> tier - 2 | O6: =VLOOKUP(A6,'Hospitalisation Details'!A:K,10,FALSE) -> tier - 2 | P6: =VLOOKUP(A6,'Hospitalisation Details'!A:K,11,FALSE) -> R1013 | Q6: =VLOOKUP(A6,'Hospitalisation Details'!A:K,4,FALSE) -> 1
A7: Id2261 | B7: =VLOOKUP(A7,'Customer Names'!A:F,4,FALSE) -> Julia | C7: =VLOOKUP(A7,'Medical Examinations'!A:J,2,FALSE) -> 17.44 | D7: =VLOOKUP(A7,'Medical Examinations'!A:J,4,FALSE) -> 4.42 | E7: =VLOOKUP(A7,'Medical Examinations'!A:J,6,FALSE) -> yes | F7: =VLOOKUP(A7,'Medical Examinations'!A:J,7,FALSE) -> No | G7: =VLOOKUP(A7,'Medical Examinations'!A:J,8,FALSE) -> Yes | H7: =VLOOKUP(A7,'Medical Examinations'!A:J,9,FALSE) -> 1 | I7: =VLOOKUP(A7,'Medical Examinations'!A:J,10,FALSE) -> No | J7: =VLOOKUP(A7,'Medical Examinations'!A:J,3,FALSE) -> Underweight | K7: =VLOOKUP(A7,'Medical Examinations'!A:J,5,FALSE) -> Normal | L7: =VLOOKUP(A7,'Hospitalisation Details'!A:K,5,FALSE) -> 4-Nov-1997 | M7: =VLOOKUP(A7,'Hospitalisation Details'!A:K,8,FALSE) -> 1253 | N7: =VLOOKUP(A7,'Hospitalisation Details'!A:K,9,FALSE) -> tier - 2 | O7: =VLOOKUP(A7,'Hospitalisation Details'!A:K,10,FALSE) -> tier - 2 | P7: =VLOOKUP(A7,'Hospitalisation Details'!A:K,11,FALSE) -> R1013 | Q7: =VLOOKUP(A7,'Hospitalisation Details'!A:K,4,FALSE) -> 4
A8: Id2251 | B8: =VLOOKUP(A8,'Customer Names'!A:F,4,FALSE) -> Natalie | C8: =VLOOKUP(A8,'Medical Examinations'!A:J,2,FALSE) -> 16.13 | D8: =VLOOKUP(A8,'Medical Examinations'!A:J,4,FALSE) -> 5.56 | E8: =VLOOKUP(A8,'Medical Examinations'!A:J,6,FALSE) -> No | F8: =VLOOKUP(A8,'Medical Examinations'!A:J,7,FALSE) -> yes | G8: =VLOOKUP(A8,'Medical Examinations'!A:J,8,FALSE) -> No | H8: =VLOOKUP(A8,'Medical Examinations'!A:J,9,FALSE) -> 1 | I8: =VLOOKUP(A8,'Medical Examinations'!A:J,10,FALSE) -> No | J8: =VLOOKUP(A8,'Medical Examinations'!A:J,3,FALSE) -> Underweight | K8: =VLOOKUP(A8,'Medical Examinations'!A:J,5,FALSE) -> Normal | L8: =VLOOKUP(A8,'Hospitalisation Details'!A:K,5,FALSE) -> 26-Jun-2000 | M8: =VLOOKUP(A8,'Hospitalisation Details'!A:K,8,FALSE) -> 1286 | N8: =VLOOKUP(A8,'Hospitalisation Details'!A:K,9,FALSE) -> tier - 2 | O8: =VLOOKUP(A8,'Hospitalisation Details'!A:K,10,FALSE) -> tier - 2 | P8: =VLOOKUP(A8,'Hospitalisation Details'!A:K,11,FALSE) -> R1013 | Q8: =VLOOKUP(A8,'Hospitalisation Details'!A:K,4,FALSE) -> 26
A9: Id2250 | B9: =VLOOKUP(A9,'Customer Names'!A:F,4,FALSE) -> Mary | C9: =VLOOKUP(A9,'Medical Examinations'!A:J,2,FALSE) -> 23.88 | D9: =VLOOKUP(A9,'Medical Examinations'!A:J,4,FALSE) -> 4.51 | E9: =VLOOKUP(A9,'Medical Examinations'!A:J,6,FALSE) -> No | F9: =VLOOKUP(A9,'Medical Examinations'!A:J,7,FALSE) -> No | G9: =VLOOKUP(A9,'Medical Examinations'!A:J,8,FALSE) -> No | H9: =VLOOKUP(A9,'Medical Examinations'!A:J,9,FALSE) -> 1 | I9: =VLOOKUP(A9,'Medical Examinations'!A:J,10,FALSE) -> No | J9: =VLOOKUP(A9,'Medical Examinations'!A:J,3,FALSE) -> Normal Weight | K9: =VLOOKUP(A9,'Medical Examinations'!A:J,5,FALSE) -> Normal | L9: =VLOOKUP(A9,'Hospitalisation Details'!A:K,5,FALSE) -> 4-Jun-1998 | M9: =VLOOKUP(A9,'Hospitalisation Details'!A:K,8,FALSE) -> 1290.93 | N9: =VLOOKUP(A9,'Hospitalisation Details'!A:K,9,FALSE) -> tier - 2 | O9: =VLOOKUP(A9,'Hospitalisation Details'!A:K,10,FALSE) -> tier - 2 | P9: =VLOOKUP(A9,'Hospitalisation Details'!A:K,11,FALSE) -> R1013 | Q9: =VLOOKUP(A9,'Hospitalisation Details'!A:K,4,FALSE) -> 4
A10: Id2247 | B10: =VLOOKUP(A10,'Customer Names'!A:F,4,FALSE) -> Jessica | C10: =VLOOKUP(A10,'Medical Examinations'!A:J,2,FALSE) -> 20.43 | D10: =VLOOKUP(A10,'Medical Examinations'!A:J,4,FALSE) -> 4.54 | E10: =VLOOKUP(A10,'Medical Examinations'!A:J,6,FALSE) -> No | F10: =VLOOKUP(A10,'Medical Examinations'!A:J,7,FALSE) -> No | G10: =VLOOKUP(A10,'Medical Examinations'!A:J,8,FALSE) -> No | H10: =VLOOKUP(A10,'Medical Examinations'!A:J,9,FALSE) -> 0 | I10: =VLOOKUP(A10,'Medical Examinations'!A:J,10,FALSE) -> No | J10: =VLOOKUP(A10,'Medical Examinations'!A:J,3,FALSE) -> Normal Weight | K10: =VLOOKUP(A10,'Medical Examinations'!A:J,5,FALSE) -> Normal | L10: =VLOOKUP(A10,'Hospitalisation Details'!A:K,5,FALSE) -> 2-Dec-1999 | M10: =VLOOKUP(A10,'Hospitalisation Details'!A:K,8,FALSE) -> 1304 | N10: =VLOOKUP(A10,'Hospitalisation Details'!A:K,9,FALSE) -> tier - 2 | O10: =VLOOKUP(A10,'Hospitalisation Details'!A:K,10,FALSE) -> tier - 2 | P10: =VLOOKUP(A10,'Hospitalisation Details'!A:K,11,FALSE) -> R1013 | Q10: =VLOOKUP(A10,'Hospitalisation Details'!A:K,4,FALSE) -> 2
A11: Id2246 | B11: =VLOOKUP(A11,'Customer Names'!A:F,4,FALSE) -> Melanie | C11: =VLOOKUP(A11,'Medical Examinations'!A:J,2,FALSE) -> 20.88 | D11: =VLOOKUP(A11,'Medical Examinations'!A:J,4,FALSE) -> 7.4 | E11: =VLOOKUP(A11,'Medical Examinations'!A:J,6,FALSE) -> No | F11: =VLOOKUP(A11,'Medical Examinations'!A:J,7,FALSE) -> No | G11: =VLOOKUP(A11,'Medical Examinations'!A:J,8,FALSE) -> No | H11: =VLOOKUP(A11,'Medical Examinations'!A:J,9,FALSE) -> 0 | I11: =VLOOKUP(A11,'Medical Examinations'!A:J,10,FALSE) -> No | J11: =VLOOKUP(A11,'Medical Examinations'!A:J,3,FALSE) -> Normal Weight | K11: =VLOOKUP(A11,'Medical Examinations'!A:J,5,FALSE) -> Diabetes | L11: =VLOOKUP(A11,'Hospitalisation Details'!A:K,5,FALSE) -> 13-Oct-2002 | M11: =VLOOKUP(A11,'Hospitalisation Details'!A:K,8,FALSE) -> 1315 | N11: =VLOOKUP(A11,'Hospitalisation Details'!A:K,9,FALSE) -> tier - 2 | O11: =VLOOKUP(A11,'Hospitalisation Details'!A:K,10,FALSE) -> tier - 2 | P11: =VLOOKUP(A11,'Hospitalisation Details'!A:K,11,FALSE) -> R1013 | Q11: =VLOOKUP(A11,'Hospitalisation Details'!A:K,4,FALSE) -> 13
A12: Id2239 | B12: =VLOOKUP(A12,'Customer Names'!A:F,4,FALSE) -> William R | C12: =VLOOKUP(A12,'Medical Examinations'!A:J,2,FALSE) -> 18.58 | D12: =VLOOKUP(A12,'Medical Examinations'!A:J,4,FALSE) -> 6.22 | E12: =VLOOKUP(A12,'Medical Examinations'!A:J,6,FALSE) -> No | F12: =VLOOKUP(A12,'Medical Examinations'!A:J,7,FALSE) -> No | G12: =VLOOKUP(A12,'Medical Examinations'!A:J,8,FALSE) -> No | H12: =VLOOKUP(A12,'Medical Examinations'!A:J,9,FALSE) -> 0 | I12: =VLOOKUP(A12,'Medical Examinations'!A:J,10,FALSE) -> No | J12: =VLOOKUP(A12,'Medical Examinations'!A:J,3,FALSE) -> Normal Weight | K12: =VLOOKUP(A12,'Medical Examinations'!A:J,5,FALSE) -> Prediabetes | L12: =VLOOKUP(A12,'Hospitalisation Details'!A:K,5,FALSE) -> 6-Jul-1999 | M12: =VLOOKUP(A12,'Hospitalisation Details'!A:K,8,FALSE) -> 1389 | N12: =VLOOKUP(A12,'Hospitalisation Details'!A:K,9,FALSE) -> tier - 2 | O12: =VLOOKUP(A12,'Hospitalisation Details'!A:K,10,FALSE) -> tier - 2 | P12: =VLOOKUP(A12,'Hospitalisation Details'!A:K,11,FALSE) -> R1013 | Q12: =VLOOKUP(A12,'Hospitalisation Details'!A:K,4,FALSE) -> 6
A13: Id2238 | B13: =VLOOKUP(A13,'Customer Names'!A:F,4,FALSE) -> Christopher S. | C13: =VLOOKUP(A13,'Medical Examinations'!A:J,2,FALSE) -> 18.5 | D13: =VLOOKUP(A13,'Medical Examinations'!A:J,4,FALSE) -> 11.84 | E13: =VLOOKUP(A13,'Medical Examinations'!A:J,6,FALSE) -> No | F13: =VLOOKUP(A13,'Medical Examinations'!A:J,7,FALSE) -> No | G13: =VLOOKUP(A13,'Medical Examinations'!A:J,8,FALSE) -> No | H13: =VLOOKUP(A13,'Medical Examinations'!A:J,9,FALSE) -> 0 | I13: =VLOOKUP(A13,'Medical Examinations'!A:J,10,FALSE) -> No | J13: =VLOOKUP(A13,'Medical Examinations'!A:J,3,FALSE) -> Normal Weight | K13: =VLOOKUP(A13,'Medical Examinations'!A:J,5,FALSE) -> Diabetes | L13: =VLOOKUP(A13,'Hospitalisation Details'!A:K,5,FALSE) -> 14-Nov-2002 | M13: =VLOOKUP(A13,'Hospitalisation Details'!A:K,8,FALSE) -> 1390 | N13: =VLOOKUP(A13,'Hospitalisation Details'!A:K,9,FALSE) -> tier - 2 | O13: =VLOOKUP(A13,'Hospitalisation Details'!A:K,10,FALSE) -> tier - 2 | P13: =VLOOKUP(A13,'Hospitalisation Details'!A:K,11,FALSE) -> R1013 | Q13: =VLOOKUP(A13,'Hospitalisation Details'!A:K,4,FALSE) -> 14
... A2336: Id210 | B2336: =VLOOKUP(A2336,'Customer Names'!A:F,4,FALSE) -> Kate L | C2336: =VLOOKUP(A2336,'Medical Examinations'!A:J,2,FALSE) -> 31.02 | D2336: =VLOOKUP(A2336,'Medical Examinations'!A:J,4,FALSE) -> 4.56 | E2336: =VLOOKUP(A2336,'Medical Examinations'!A:J,6,FALSE) -> No | F2336: =VLOOKUP(A2336,'Medical Examinations'!A:J,7,FALSE) -> yes | G2336: =VLOOKUP(A2336,'Medical Examinations'!A:J,8,FALSE) -> No | H2336: =VLOOKUP(A2336,'Medical Examinations'!A:J,9,FALSE) -> 1 | I2336: =VLOOKUP(A2336,'Medical Examinations'!A:J,10,FALSE) -> yes | J2336: =VLOOKUP(A2336,'Medical Examinations'!A:J,3,FALSE) -> Obesity | K2336: =VLOOKUP(A2336,'Medical Examinations'!A:J,5,FALSE) -> Normal | L2336: =VLOOKUP(A2336,'Hospitalisation Details'!A:K,5,FALSE) -> 17-Dec-2000 | M2336: =VLOOKUP(A2336,'Hospitalisation Details'!A:K,8,FALSE) -> 35595.59 | N2336: =VLOOKUP(A2336,'Hospitalisation Details'!A:K,9,FALSE) -> tier - 2 | O2336: =VLOOKUP(A2336,'Hospitalisation Details'!A:K,10,FALSE) -> tier - 3 | P2336: =VLOOKUP(A2336,'Hospitalisation Details'!A:K,11,FALSE) -> R1013 | Q2336: =VLOOKUP(A2336,'Hospitalisation Details'!A:K,4,FALSE) -> 17

Sheet Hospitalisation Details
A1: Customer ID | B1: year | C1: month | D1: date | E1: Date of biirth | F1: Age | G1: children | H1: charges | I1: Hospital tier | J1: City tier | K1: State ID
A2: Id2285 | B2: 2004 | C2: Jun | D2: 10 | E2: =CONCATENATE(D2,"-",C2,"-",B2) -> 10-Jun-2004 | F2: =DATEDIF(E2,DATE(2023,6,8),"Y") -> 18 | G2: 0 | H2: 1146.8 | I2: tier - 2 | J2: tier - 2 | K2: R1013
A3: Id2283 | B3: 2004 | C3: Jul | D3: 18 | E3: =CONCATENATE(D3,"-",C3,"-",B3) -> 18-Jul-2004 | F3: =DATEDIF(E3,DATE(2023,6,8),"Y") -> 18 | G3: 0 | H3: 1149.4 | I3: tier - 2 | J3: tier - 2 | K3: R1013
A4: Id2277 | B4: 1997 | C4: Jun | D4: 28 | E4: =CONCATENATE(D4,"-",C4,"-",B4) -> 28-Jun-1997 | F4: =DATEDIF(E4,DATE(2023,6,8),"Y") -> 25 | G4: 0 | H4: 1178.07 | I4: tier - 2 | J4: tier - 2 | K4: R1013 | N4: Average year | P4: =AVERAGE(B:B) -> 1982.8415
A5: Id2268 | B5: 2002 | C5: Dec | D5: 12 | E5: =CONCATENATE(D5,"-",C5,"-",B5) -> 12-Dec-2002 | F5: =DATEDIF(E5,DATE(2023,6,8),"Y") -> 20 | G5: 0 | H5: 1237 | I5: tier - 2 | J5: tier - 2 | K5: R1013 | N5: Nearest integer | P5: 1983
A6: Id2266 | B6: 2002 | C6: Jul | D6: 1 | E6: =CONCATENATE(D6,"-",C6,"-",B6) -> 1-Jul-2002 | F6: =DATEDIF(E6,DATE(2023,6,8),"Y") -> 20 | G6: 0 | H6: 1241 | I6: tier - 2 | J6: tier - 2 | K6: R1013
A7: Id2261 | B7: 1997 | C7: Nov | D7: 4 | E7: =CONCATENATE(D7,"-",C7,"-",B7) -> 4-Nov-1997 | F7: =DATEDIF(E7,DATE(2023,6,8),"Y") -> 25 | G7: 0 | H7: 1253 | I7: tier - 2 | J7: tier - 2 | K7: R1013
A8: Id2251 | B8: 2000 | C8: Jun | D8: 26 | E8: =CONCATENATE(D8,"-",C8,"-",B8) -> 26-Jun-2000 | F8: =DATEDIF(E8,DATE(2023,6,8),"Y") -> 22 | G8: 0 | H8: 1286 | I8: tier - 2 | J8: tier - 2 | K8: R1013 | N8: Most frequently occuring values in hospital tier
A9: Id2250 | B9: 1998 | C9: Jun | D9: 4 | E9: =CONCATENATE(D9,"-",C9,"-",B9) -> 4-Jun-1998 | F9: =DATEDIF(E9,DATE(2023,6,8),"Y") -> 25 | G9: 0 | H9: 1290.93 | I9: tier - 2 | J9: tier - 2 | K9: R1013
A10: Id2247 | B10: 1999 | C10: Dec | D10: 2 | E10: =CONCATENATE(D10,"-",C10,"-",B10) -> 2-Dec-1999 | F10: =DATEDIF(E10,DATE(2023,6,8),"Y") -> 23 | G10: 0 | H10: 1304 | I10: tier - 2 | J10: tier - 2 | K10: R1013 | N10: tier-2 | O10: =COUNTIF(I:I,"tier - 2") -> 1339
A11: Id2246 | B11: 2002 | C11: Oct | D11: 13 | E11: =CONCATENATE(D11,"-",C11,"-",B11) -> 13-Oct-2002 | F11: =DATEDIF(E11,DATE(2023,6,8),"Y") -> 20 | G11: 0 | H11: 1315 | I11: tier - 2 | J11: tier - 2 | K11: R1013 | N11: tier-3 | O11: =COUNTIF(I:I,"tier - 3") -> 694
A12: Id2239 | B12: 1999 | C12: Jul | D12: 6 | E12: =CONCATENATE(D12,"-",C12,"-",B12) -> 6-Jul-1999 | F12: =DATEDIF(E12,DATE(2023,6,8),"Y") -> 23 | G12: 0 | H12: 1389 | I12: tier - 2 | J12: tier - 2 | K12: R1013 | N12: tier-1 | O12: =COUNTIF(I:I,"tier - 1") -> 309
A13: Id2238 | B13: 2002 | C13: Nov | D13: 14 | E13: =CONCATENATE(D13,"-",C13,"-",B13) -> 14-Nov-2002 | F13: =DATEDIF(E13,DATE(2023,6,8),"Y") -> 20 | G13: 0 | H13: 1390 | I13: tier - 2 | J13: tier - 2 | K13: R1013
A14: Id2236 | B14: 1998 | C14: Sep | D14: 5 | E14: =CONCATENATE(D14,"-",C14,"-",B14) -> 5-Sep-1998 | F14: =DATEDIF(E14,DATE(2023,6,8),"Y") -> 24 | G14: 0 | H14: 1400.44 | I14: tier - 2 | J14: tier - 2 | K14: R1013 | N14: Most frequently occuring value in city tier
A15: Id2233 | B15: 2001 | C15: Aug | D15: 23 | E15: =CONCATENATE(D15,"-",C15,"-",B15) -> 23-Aug-2001 | F15: =DATEDIF(E15,DATE(2023,6,8),"Y") -> 21 | G15: 0 | H15: 1421 | I15: tier - 2 | J15: tier - 2 | K15: R1013
A16: Id2232 | B16: 1997 | C16: Dec | D16: 5 | E16: =CONCATENATE(D16,"-",C16,"-",B16) -> 5-Dec-1997 | F16: =DATEDIF(E16,DATE(2023,6,8),"Y") -> 25 | G16: 0 | H16: 1422 | I16: tier - 2 | J16: tier - 2 | K16: R1013 | N16: tier-1 | O16: =COUNTIF(J:J,"tier - 1") -> 734
A17: Id2231 | B17: 2000 | C17: Sep | D17: 1 | E17: =CONCATENATE(D17,"-",C17,"-",B17) -> 1-Sep-2000 | F17: =DATEDIF(E17,DATE(2023,6,8),"Y") -> 22 | G17: 0 | H17: 1438 | I17: tier - 2 | J17: tier - 2 | K17: R1013 | N17: tier-2 | O17: =COUNTIF(J:J,"tier - 2") -> 812
A18: Id2229 | B18: 2003 | C18: Jun | D18: 20 | E18: =CONCATENATE(D18,"-",C18,"-",B18) -> 20-Jun-2003 | F18: =DATEDIF(E18,DATE(2023,6,8),"Y") -> 19 | G18: 0 | H18: 1467 | I18: tier - 2 | J18: tier - 2 | K18: R1013 | N18: tier-3 | O18: =COUNTIF(J:J,"tier - 3") -> 796
A19: Id2225 | B19: 1998 | C19: Jun | D19: 19 | E19: =CONCATENATE(D19,"-",C19,"-",B19) -> 19-Jun-1998 | F19: =DATEDIF(E19,DATE(2023,6,8),"Y") -> 24 | G19: 0 | H19: 1497 | I19: tier - 2 | J19: tier - 2 | K19: R1013
A20: Id2222 | B20: 2001 | C20: Jun | D20: 2 | E20: =CONCATENATE(D20,"-",C20,"-",B20) -> 2-Jun-2001 | F20: =DATEDIF(E20,DATE(2023,6,8),"Y") -> 22 | G20: 0 | H20: 1532.47 | I20: tier - 2 | J20: tier - 2 | K20: R1013
A21: Id2221 | B21: 2001 | C21: Dec | D21: 5 | E21: =CONCATENATE(D21,"-",C21,"-",B21) -> 5-Dec-2001 | F21: =DATEDIF(E21,DATE(2023,6,8),"Y") -> 21 | G21: 0 | H21: 1534.3 | I21: tier - 2 | J21: tier - 2 | K21: R1013
A22: Id2215 | B22: 2004 | C22: Aug | D22: 21 | E22: =CONCATENATE(D22,"-",C22,"-",B22) -> 21-Aug-2004 | F22: =DATEDIF(E22,DATE(2023,6,8),"Y") -> 18 | G22: 0 | H22: 1621.88 | I22: tier - 2 | J22: tier - 2 | K22: R1013
A23: Id2210 | B23: 2004 | C23: Oct | D23: 4 | E23: =CONCATENATE(D23,"-",C23,"-",B23) -> 4-Oct-2004 | F23: =DATEDIF(E23,DATE(2023,6,8),"Y") -> 18 | G23: 0 | H23: 1629.83 | I23: tier - 2 | J23: tier - 2 | K23: R1013
A24: Id2205 | B24: 2004 | C24: Dec | D24: 13 | E24: =CONCATENATE(D24,"-",C24,"-",B24) -> 13-Dec-2004 | F24: =DATEDIF(E24,DATE(2023,6,8),"Y") -> 18 | G24: 0 | H24: 1633.04 | I24: tier - 2 | J24: tier - 2 | K24: R1013
A25: Id2203 | B25: 2004 | C25: Jun | D25: 13 | E25: =CONCATENATE(D25,"-",C25,"-",B25) -> 13-Jun-2004 | F25: =DATEDIF(E25,DATE(2023,6,8),"Y") -> 18 | G25: 0 | H25: 1634.57 | I25: tier - 2 | J25: tier - 2 | K25: R1013
A26: Id2198 | B26: 2000 | C26: Oct | D26: 23 | E26: =CONCATENATE(D26,"-",C26,"-",B26) -> 23-Oct-2000 | F26: =DATEDIF(E26,DATE(2023,6,8),"Y") -> 22 | G26: 0 | H26: 1665 | I26: tier - 2 | J26: tier - 2 | K26: R1013
A27: Id2197 | B27: 2000 | C27: Jun | D27: 10 | E27: =CONCATENATE(D27,"-",C27,"-",B27) -> 10-Jun-2000 | F27: =DATEDIF(E27,DATE(2023,6,8),"Y") -> 22 | G27: 0 | H27: 1674.63 | I27: tier - 2 | J27: tier - 2 | K27: R1013
A28: Id2121 | B28: 2000 | C28: Dec | D28: 10 | E28: =CONCATENATE(D28,"-",C28,"-",B28) -> 10-Dec-2000 | F28: =DATEDIF(E28,DATE(2023,6,8),"Y") -> 22 | G28: 0 | H28: 2156.75 | I28: tier - 2 | J28: tier - 2 | K28: R1013
A29: Id2119 | B29: 1994 | C29: Sep | D29: 27 | E29: =CONCATENATE(D29,"-",C29,"-",B29) -> 27-Sep-1994 | F29: =DATEDIF(E29,DATE(2023,6,8),"Y") -> 28 | G29: 0 | H29: 2170.08 | I29: tier - 2 | J29: tier - 2 | K29: R1013
A30: Id2108 | B30: 1994 | C30: Nov | D30: 17 | E30: =CONCATENATE(D30,"-",C30,"-",B30) -> 17-Nov-1994 | F30: =DATEDIF(E30,DATE(2023,6,8),"Y") -> 28 | G30: 0 | H30: 2213.21 | I30: tier - 2 | J30: tier - 2 | K30: R1013
... A931: Id1367 | B931: 1977 | C931: Jul | D931: 20 | E931: =CONCATENATE(D931,"-",C931,"-",B931) -> 20-Jul-1977 | F931: =DATEDIF(E931,DATE(2023,6,8),"Y") -> 45 | G931: 0 | H931: 7935.29 | I931: tier - 2 | J931: tier - 1 | K931: R1024
A932: Id1289 | C932: Jul | D932: 24 | E932: =CONCATENATE(D932,"-",C932,"-",B932) -> 24-Jul- | F932: =DATEDIF(E932,DATE(2023,6,8),"Y") -> #VALUE! | G932: 0 | H932: 8534.67 | I932: tier - 2 | J932: tier - 3 | K932: R1024
A933: Id1183 | B933: 1972 | C933: Sep | D933: 22 | E933: =CONCATENATE(D933,"-",C933,"-",B933) -> 22-Sep-1972 | F933: =DATEDIF(E933,DATE(2023,6,8),"Y") -> 50 | G933: 0 | H933: 9541.7 | I933: tier - 2 | J933: tier - 1 | K933: R1024
A934: Id1142 | B934: 1971 | C934: Nov | D934: 9 | E934: =CONCATENATE(D934,"-",C934,"-",B934) -> 9-Nov-1971 | F934: =DATEDIF(E934,DATE(2023,6,8),"Y") -> 51 | G934: 0 | H934: 9866.3 | I934: tier - 2 | J934: tier - 3 | K934: R1024
A935: Id1138 | B935: 1971 | C935: Jul | D935: 3 | E935: =CONCATENATE(D935,"-",C935,"-",B935) -> 3-Jul-1971 | F935: =DATEDIF(E935,DATE(2023,6,8),"Y") -> 51 | G935: 0 | H935: 9875.68 | I935: tier - 2 | J935: tier - 3 | K935: R1024
A936: Id1108 | B936: 1970 | C936: Dec | D936: 24 | E936: =CONCATENATE(D936,"-",C936,"-",B936) -> 24-Dec-1970 | F936: =DATEDIF(E936,DATE(2023,6,8),"Y") -> 52 | G936: 0 | H936: 10197.77 | I936: tier - 3 | J936: tier - 1 | K936: R1024
A937: Id1101 | B937: 1970 | C937: Jun | D937: 21 | E937: =CONCATENATE(D937,"-",C937,"-",B937) -> 21-Jun-1970 | F937: =DATEDIF(E937,DATE(2023,6,8),"Y") -> 52 | G937: 0 | H937: 10274.33 | I937: tier - 3 | J937: tier - 1 | K937: R1024
A938: Id1067 | B938: 1969 | C938: Jul | D938: 17 | E938: =CONCATENATE(D938,"-",C938,"-",B938) -> 17-Jul-1969 | F938: =DATEDIF(E938,DATE(2023,6,8),"Y") -> 53 | G938: 0 | H938: 10564.88 | I938: tier - 3 | J938: tier - 1 | K938: R1024
A939: Id1034 | B939: 1968 | C939: Nov | D939: 13 | E939: =CONCATENATE(D939,"-",C939,"-",B939) -> 13-Nov-1968 | F939: =DATEDIF(E939,DATE(2023,6,8),"Y") -> 54 | G939: 0 | H939: 10923.93 | I939: tier - 3 | J939: tier - 1 | K939: R1024
A940: Id994 | B940: 1967 | C940: Jun | D940: 14 | E940: =CONCATENATE(D940,"-",C940,"-",B940) -> 14-Jun-1967 | F940: =DATEDIF(E940,DATE(2023,6,8),"Y") -> 55 | G940: 0 | H940: 11286.54 | I940: tier - 3 | J940: tier - 3 | K940: R1024
...

Sheet Sheet2

Sheet Medical Examinations
A1: Customer ID | B1: BMI | C1: Weight Status | D1: HBA1C | E1: Diabetes Status | F1: Heart Issues | G1: Any Transplants | H1: Cancer history | I1: NumberOfMajorSurgeries | J1: smoker
A2: Id292 | B2: 29.735 | C2: =IF(B2<18.5,"Underweight", IF(B2<=24.9,"Normal Weight", IF(B2<=29.9,"Overweight","Obesity"))) -> Overweight | D2: 7.79 | E2: =IF(D2<5.7,"Normal", IF(D2<=6.4,"Prediabetes","Diabetes")) -> Diabetes | F2: No | G2: No | H2: No | I2: 0 | J2: No
A3: Id298 | B3: 36.86 | C3: =IF(B3<18.5,"Underweight", IF(B3<=24.9,"Normal Weight", IF(B3<=29.9,"Overweight","Obesity"))) -> Obesity | D3: 11.95 | E3: =IF(D3<5.7,"Normal", IF(D3<=6.4,"Prediabetes","Diabetes")) -> Diabetes | F3: No | G3: No | H3: No | I3: 0 | J3: No
A4: Id317 | B4: 28.595 | C4: =IF(B4<18.5,"Underweight", IF(B4<=24.9,"Normal Weight", IF(B4<=29.9,"Overweight","Obesity"))) -> Overweight | D4: 10.21 | E4: =IF(D4<5.7,"Normal", IF(D4<=6.4,"Prediabetes","Diabetes")) -> Diabetes | F4: No | G4: No | H4: No | I4: 0 | J4: No
A5: Id348 | B5: 25.84 | C5: =IF(B5<18.5,"Underweight", IF(B5<=24.9,"Normal Weight", IF(B5<=29.9,"Overweight","Obesity"))) -> Overweight | D5: 8.83 | E5: =IF(D5<5.7,"Normal", IF(D5<=6.4,"Prediabetes","Diabetes")) -> Diabetes | F5: No | G5: No | H5: No | I5: 0 | J5: No
A6: Id352 | B6: 41.42 | C6: =IF(B6<18.5,"Underweight", IF(B6<=24.9,"Normal Weight", IF(B6<=29.9,"Overweight","Obesity"))) -> Obesity | D6: 6.07 | E6: =IF(D6<5.7,"Normal", IF(D6<=6.4,"Prediabetes","Diabetes")) -> Prediabetes | F6: No | G6: No | H6: No | I6: 0 | J6: No
A7: Id353 | B7: 36.67 | C7: =IF(B7<18.5,"Underweight", IF(B7<=24.9,"Normal Weight", IF(B7<=29.9,"Overweight","Obesity"))) -> Obesity | D7: 10.21 | E7: =IF(D7<5.7,"Normal", IF(D7<=6.4,"Prediabetes","Diabetes")) -> Diabetes | F7: No | G7: No | H7: No | I7: 0 | J7: No | Q7: Most frequently occuring values in smoker
A8: Id354 | B8: 27.645 | C8: =IF(B8<18.5,"Underweight", IF(B8<=24.9,"Normal Weight", IF(B8<=29.9,"Overweight","Obesity"))) -> Overweight | D8: 4.69 | E8: =IF(D8<5.7,"Normal", IF(D8<=6.4,"Prediabetes","Diabetes")) -> Normal | F8: No | G8: No | H8: No | I8: 0 | J8: No
A9: Id366 | B9: 35.31 | C9: =IF(B9<18.5,"Underweight", IF(B9<=24.9,"Normal Weight", IF(B9<=29.9,"Overweight","Obesity"))) -> Obesity | D9: 9.04 | E9: =IF(D9<5.7,"Normal", IF(D9<=6.4,"Prediabetes","Diabetes")) -> Diabetes | F9: No | G9: No | H9: No | I9: 0 | J9: No | R9: Yes | S9: =COUNTIF(J:J,"YES") -> 488
A10: Id378 | B10: 31.9 | C10: =IF(B10<18.5,"Underweight", IF(B10<=24.9,"Normal Weight", IF(B10<=29.9,"Overweight","Obesity"))) -> Obesity | D10: 11.89 | E10: =IF(D10<5.7,"Normal", IF(D10<=6.4,"Prediabetes","Diabetes")) -> Diabetes | F10: No | G10: No | H10: No | I10: 0 | J10: No | R10: No | S10: =COUNTIF(J:J,"No") -> 1847
A11: Id385 | B11: 31.46 | C11: =IF(B11<18.5,"Underweight", IF(B11<=24.9,"Normal Weight", IF(B11<=29.9,"Overweight","Obesity"))) -> Obesity | D11: 7.39 | E11: =IF(D11<5.7,"Normal", IF(D11<=6.4,"Prediabetes","Diabetes")) -> Diabetes | F11: No | G11: No | H11: No | I11: 0 | J11: No
A12: Id393 | B12: 35.91 | C12: =IF(B12<18.5,"Underweight", IF(B12<=24.9,"Normal Weight", IF(B12<=29.9,"Overweight","Obesity"))) -> Obesity | D12: 8.71 | E12: =IF(D12<5.7,"Normal", IF(D12<=6.4,"Prediabetes","Diabetes")) -> Diabetes | F12: No | G12: No | H12: No | I12: 0 | J12: No
A13: Id405 | B13: 25.46 | C13: =IF(B13<18.5,"Underweight", IF(B13<=24.9,"Normal Weight", IF(B13<=29.9,"Overweight","Obesity"))) -> Overweight | D13: 11.75 | E13: =IF(D13<5.7,"Normal", IF(D13<=6.4,"Prediabetes","Diabetes")) -> Diabetes | F13: No | G13: No | H13: No | I13: 0 | J13: No
A14: Id425 | B14: 30.02 | C14: =IF(B14<18.5,"Underweight", IF(B14<=24.9,"Normal Weight", IF(B14<=29.9,"Overweight","Obesity"))) -> Obesity | D14: 11.09 | E14: =IF(D14<5.7,"Normal", IF(D14<=6.4,"Prediabetes","Diabetes")) -> Diabetes | F14: No | G14: No | H14: No | I14: 0 | J14: No
A15: Id440 | B15: 24.32 | C15: =IF(B15<18.5,"Underweight", IF(B15<=24.9,"Normal Weight", IF(B15<=29.9,"Overweight","Obesity"))) -> Normal Weight | D15: 6.39 | E15: =IF(D15<5.7,"Normal", IF(D15<=6.4,"Prediabetes","Diabetes")) -> Prediabetes | F15: No | G15: No | H15: No | I15: 0 | J15: No
A16: Id450 | B16: 24.225 | C16: =IF(B16<18.5,"Underweight", IF(B16<=24.9,"Normal Weight", IF(B16<=29.9,"Overweight","Obesity"))) -> Normal Weight | D16: 4.09 | E16: =IF(D16<5.7,"Normal", IF(D16<=6.4,"Prediabetes","Diabetes")) -> Normal | F16: No | G16: No | H16: No | I16: 0 | J16: No
A17: Id453 | B17: 23.98 | C17: =IF(B17<18.5,"Underweight", IF(B17<=24.9,"Normal Weight", IF(B17<=29.9,"Overweight","Obesity"))) -> Normal Weight | D17: 10.67 | E17: =IF(D17<5.7,"Normal", IF(D17<=6.4,"Prediabetes","Diabetes")) -> Diabetes | F17: No | G17: No | H17: No | I17: 0 | J17: No
A18: Id456 | B18: 22.705 | C18: =IF(B18<18.5,"Underweight", IF(B18<=24.9,"Normal Weight", IF(B18<=29.9,"Overweight","Obesity"))) -> Normal Weight | D18: 5.27 | E18: =IF(D18<5.7,"Normal", IF(D18<=6.4,"Prediabetes","Diabetes")) -> Normal | F18: No | G18: No | H18: No | I18: 0 | J18: No
A19: Id464 | B19: 55.05 | C19: =IF(B19<18.5,"Underweight", IF(B19<=24.9,"Normal Weight", IF(B19<=29.9,"Overweight","Obesity"))) -> Obesity | D19: 7.66 | E19: =IF(D19<5.7,"Normal", IF(D19<=6.4,"Prediabetes","Diabetes")) -> Diabetes | F19: No | G19: No | H19: No | I19: 0 | J19: No
A20: Id466 | B20: 18.715 | C20: =IF(B20<18.5,"Underweight", IF(B20<=24.9,"Normal Weight", IF(B20<=29.9,"Overweight","Obesity"))) -> Normal Weight | D20: 4.44 | E20: =IF(D20<5.7,"Normal", IF(D20<=6.4,"Prediabetes","Diabetes")) -> Normal | F20: No | G20: No | H20: No | I20: 0 | J20: No
A21: Id471 | B21: 29.6 | C21: =IF(B21<18.5,"Underweight", IF(B21<=24.9,"Normal Weight", IF(B21<=29.9,"Overweight","Obesity"))) -> Overweight | D21: 8.1 | E21: =IF(D21<5.7,"Normal", IF(D21<=6.4,"Prediabetes","Diabetes")) -> Diabetes | F21: No | G21: No | H21: No | I21: 0 | J21: No
A22: Id481 | B22: 40.28 | C22: =IF(B22<18.5,"Underweight", IF(B22<=24.9,"Normal Weight", IF(B22<=29.9,"Overweight","Obesity"))) -> Obesity | D22: 8.9 | E22: =IF(D22<5.7,"Normal", IF(D22<=6.4,"Prediabetes","Diabetes")) -> Diabetes | F22: No | G22: No | H22: No | I22: 0 | J22: No
... A857: Id2330 | B857: 22.24 | C857: =IF(B857<18.5,"Underweight", IF(B857<=24.9,"Normal Weight", IF(B857<=29.9,"Overweight","Obesity"))) -> Normal Weight | D857: 4.29 | E857: =IF(D857<5.7,"Normal", IF(D857<=6.4,"Prediabetes","Diabetes")) -> Normal | F857: yes | G857: No | H857: No | I857: 0 | J857: No
A858: Id410 | B858: 23.21 | C858: =IF(B858<18.5,"Underweight", IF(B858<=24.9,"Normal Weight", IF(B858<=29.9,"Overweight","Obesity"))) -> Normal Weight | D858: 6.03 | E858: =IF(D858<5.7,"Normal", IF(D858<=6.4,"Prediabetes","Diabetes")) -> Prediabetes | F858: No | G858: No | H858: No | I858: 1 | J858: No
A859: Id413 | B859: 38.095 | C859: =IF(B859<18.5,"Underweight", IF(B859<=24.9,"Normal Weight", IF(B859<=29.9,"Overweight","Obesity"))) -> Obesity | D859: 4.76 | E859: =IF(D859<5.7,"Normal", IF(D859<=6.4,"Prediabetes","Diabetes")) -> Normal | F859: No | G859: No | H859: No | I859: 1 | J859: No
A860: Id508 | B860: 39.71 | C860: =IF(B860<18.5,"Underweight", IF(B860<=24.9,"Normal Weight", IF(B860<=29.9,"Overweight","Obesity"))) -> Obesity | D860: 5.83 | E860: =IF(D860<5.7,"Normal", IF(D860<=6.4,"Prediabetes","Diabetes")) -> Prediabetes | F860: No | G860: No | H860: No | I860: 1 | J860: No
A861: Id522 | B861: 38.83 | C861: =IF(B861<18.5,"Underweight", IF(B861<=24.9,"Normal Weight", IF(B861<=29.9,"Overweight","Obesity"))) -> Obesity | D861: 6.36 | E861: =IF(D861<5.7,"Normal", IF(D861<=6.4,"Prediabetes","Diabetes")) -> Prediabetes | F861: No | G861: No | H861: No | I861: 1 | J861: No
A862: Id523 | B862: 27.6 | C862: =IF(B862<18.5,"Underweight", IF(B862<=24.9,"Normal Weight", IF(B862<=29.9,"Overweight","Obesity"))) -> Overweight | D862: 5.36 | E862: =IF(D862<5.7,"Normal", IF(D862<=6.4,"Prediabetes","Diabetes")) -> Normal | F862: No | G862: No | H862: No | I862: 1 | J862: No
A863: Id578 | B863: 33.63 | C863: =IF(B863<18.5,"Underweight", IF(B863<=24.9,"Normal Weight", IF(B863<=29.9,"Overweight","Obesity"))) -> Obesity | D863: 5.69 | E863: =IF(D863<5.7,"Normal", IF(D863<=6.4,"Prediabetes","Diabetes")) -> Normal | F863: No | G863: No | H863: No | I863: 1 | J863: No
A864: Id612 | B864: 54.85 | C864: =IF(B864<18.5,"Underweight", IF(B864<=24.9,"Normal Weight", IF(B864<=29.9,"Overweight","Obesity"))) -> Obesity | D864: 4.9 | E864: =IF(D864<5.7,"Normal", IF(D864<=6.4,"Prediabetes","Diabetes")) -> Normal | F864: No | G864: No | H864: No | I864: 1 | J864: No
A865: Id716 | B865: 44.98 | C865: =IF(B865<18.5,"Underweight", IF(B865<=24.9,"Normal Weight", IF(B865<=29.9,"Overweight","Obesity"))) -> Obesity | D865: 5.94 | E865: =IF(D865<5.7,"Normal", IF(D865<=6.4,"Prediabetes","Diabetes")) -> Prediabetes | F865: No | G865: No | H865: No | I865: 1 | J865: No
A866: Id749 | B866: 42.81 | C866: =IF(B866<18.5,"Underweight", IF(B866<=24.9,"Normal Weight", IF(B866<=29.9,"Overweight","Obesity"))) -> Obesity | D866: 4.15 | E866: =IF(D866<5.7,"Normal", IF(D866<=6.4,"Prediabetes","Diabetes")) -> Normal | F866: No | G866: No | H866: No | I866: 1 | J866: No
A867: Id754 | B867: 53.58 | C867: =IF(B867<18.5,"Underweight", IF(B867<=24.9,"Normal Weight", IF(B867<=29.9,"Overweight","Obesity"))) -> Obesity | D867: 4.55 | E867: =IF(D867<5.7,"Normal", IF(D867<=6.4,"Prediabetes","Diabetes")) -> Normal | F867: No | G867: No | H867: No | I867: 1 | J867: No
A868: Id771 | B868: 52.41 | C868: =IF(B868<18.5,"Underweight", IF(B868<=24.9,"Normal Weight", IF(B868<=29.9,"Overweight","Obesity"))) -> Obesity | D868: 5.99 | E868: =IF(D868<5.7,"Normal", IF(D868<=6.4,"Prediabetes","Diabetes")) -> Prediabetes | F868: No | G868: No | H868: No | I868: 1 | J868: No
A869: Id775 | B869: 42.06 | C869: =IF(B869<18.5,"Underweight", IF(B869<=24.9,"Normal Weight", IF(B869<=29.9,"Overweight","Obesity"))) -> Obesity | D869: 5.32 | E869: =IF(D869<5.7,"Normal", IF(D869<=6.4,"Prediabetes","Diabetes")) -> Normal | F869: No | G869: No | H869: No | I869: 1 | J869: No
... A2117: Id683 | B2117: 20.52 | C2117: =IF(B2117<18.5,"Underweight", IF(B2117<=24.9,"Normal Weight", IF(B2117<=29.9,"Overweight","Obesity"))) -> Normal Weight | D2117: 5.45 | E2117: =IF(D2117<5.7,"Normal", IF(D2117<=6.4,"Prediabetes","Diabetes")) -> Normal | F2117: No | G2117: No | H2117: No | I2117: 1 | J2117: yes
A2118: Id32 | B2118: 42.35 | C2118: =IF(B2118<18.5,"Underweight", IF(B2118<=24.9,"Normal Weight", IF(B2118<=29.9,"Overweight","Obesity"))) -> Obesity | D2118: 5.08 | E2118: =IF(D2118<5.7,"Normal", IF(D2118<=6.4,"Prediabetes","Diabetes")) -> Normal | F2118: yes | G2118: No | H2118: No | I2118: 0 | J2118: yes
A2119: Id34 | B2119: 47.6 | C2119: =IF(B2119<18.5,"Underweight", IF(B2119<=24.9,"Normal Weight", IF(B2119<=29.9,"Overweight","Obesity"))) -> Obesity | D2119: 5.95 | E2119: =IF(D2119<5.7,"Normal", IF(D2119<=6.4,"Prediabetes","Diabetes")) -> Prediabetes | F2119: yes | G2119: No | H2119: No | I2119: 0 | J2119: yes
A2120: Id42 | B2120: 35.2 | C2120: =IF(B2120<18.5,"Underweight", IF(B2120<=24.9,"Normal Weight", IF(B2120<=29.9,"Overweight","Obesity"))) -> Obesity | D2120: 11.68 | E2120: =IF(D2120<5.7,"Normal", IF(D2120<=6.4,"Prediabetes","Diabetes")) -> Diabetes | F2120: yes | G2120: No | H2120: No | I2120: 0 | J2120: yes
A2121: Id62 | B2121: 51.48 | C2121: =IF(B2121<18.5,"Underweight", IF(B2121<=24.9,"Normal Weight", IF(B2121<=29.9,"Overweight","Obesity"))) -> Obesity | D2121: 9.33 | E2121: =IF(D2121<5.7,"Normal", IF(D2121<=6.4,"Prediabetes","Diabetes")) -> Diabetes | F2121: yes | G2121: No | H2121: No | I2121: 0 | J2121: yes
...
